Workbook

Sheet README
A1: MECSR DIRECTORY 2027 — CONTENT TRACKER
A2: What each signed partner is owed in the 2027 Directory, and the 384-page plan it all has to fit into.
A5: SOURCE | B5: RCM_2026_FINAL_MATRIX_v2.xlsx › sheet 'Sponsor Matrix' (OneDrive: 01. RCM PROPOSAL SIGNED), refreshed 4 Sep 2026 — 13 signed agreements, USD 1,038,198 net. Membership from your membership workbook; listings from the Brilliant Directories export of 3 Sep 2026.
A7: HOW TO USE
A8: 1 | B8: Each sheet lists only the companies holding that entitlement. If a company is not on a sheet, it bought nothing in that category.
A9: 2 | B9: BLUE TEXT is the contracted entitlement — do not edit. YELLOW cells are yours to fill in.
A10: 3 | B10: Use the Status dropdown so the Overview counts stay accurate.
A11: 4 | B11: Dates as YYYY-MM-DD. Add new agreements as a new row on each sheet where they hold an entitlement.
A13: SHEETS
A14: 01 RPM | B14: Retail People Magazine — advertising and profile features. 13 companies.
A15: 02 Ads | B15: MECSR Directory 2027 advertising placements. 8 companies.
A16: 03 Corporate Members | B16: Sponsorship-granted seats. 13 companies, 166 seats.
A17: 04 Flat Plan | B17: The full 384-page plan for 2027 — every article, feature, ad and listing block with its page numbers, the 2026 position it came from, and its production status. Includes a deadline cascade driven by one press-date cell.
A18: 05 Service Providers | B18: The 19 service-provider categories behind pages 279–297, with the verification and outreach campaign tracked per category.
A19: 06 Expert Views | B19: The nine expert-view spreads on pages 34-51, with the 2027 company, author and proposed title for each.
A20: 07 Membership | B20: The active member list as at 4 Sep 2026 — 436 active of 590, split corporate and individual/associate, each row carrying its Brilliant user id.
A21: 08 BD Reconciliation | B21: The 3 Sep 2026 Brilliant Directories extract against the print dataset: 313 listings on the site missing from print, 302 print records with no live listing, and the GLA figures needing re-verification before any ranking prints.
A22: 09 Listing Owners | B22: Every mall listing against its Brilliant account owner, and whether that owner is an active member, a lapsed member or was never one. This is what decides which outreach script each listing gets.
A23: Overview | B23: All entitlements in one table, plus live counts by status.
A25: FLAT PLAN RULES | B25: Page positions are locked to 384 (24 signatures). Changing PP on one row means taking a page from another — the TOTAL PAGES cell tells you at once if the plan no longer balances. Structural rows (listings, index, methodology) come from the master dataset and need no chasing; commercial and editorial rows do.
A27: NOT IN THIS FILE | B27: Leadership interviews and press-release mentions are Retail Congress MENA event entitlements, not Directory content. Invoice numbers and payment status are tracked separately in finance.
... A29: SHARING | B29: Share read/write with the production team via OneDrive, or commit alongside the dossier HTML to GitHub. Keep one master copy.

Sheet 01 RPM
A1: 01 · RPM — Retail People Magazine
A2: Advertising and profile features owed under the signed 2026 agreements.
A4: SN | B4: COMPANY | C4: TIER | D4: RPM AD | E4: RPM PROFILE | F4: AD: ISSUE | G4: AD: ARTWORK RECEIVED | H4: AD: STATUS | I4: PROFILE: ISSUE | J4: PROFILE: COPY RECEIVED | K4: PROFILE: STATUS | L4: OWNER | M4: NOTES
A5: 1 | B5: CENOMI CENTERS | C5: 1. DIAMOND SPONSOR | D5: Double Page | E5: Yes
A6: 2 | B6: UNIFIED REAL ESTATE DEVELOPMENT | C6: 1. DIAMOND SPONSOR | D6: Double Page | E6: Yes
A7: 3 | B7: AL OTHAIM INVESTMENT | C7: 1. DIAMOND SPONSOR | D7: Double Page | E7: Yes
A8: 4 | B8: AZAD PROPERTIES | RED MALLS | C8: 1. DIAMOND SPONSOR | D8: Double Page + 1 Full Page Ad (Q2 & Q3, add-on) | E8: Yes
A9: 5 | B9: KNOWLEDGE ECONOMIC CITY CO. | C9: 2. PLATINUM SPONSOR | D9: Double Page | E9: Yes
A10: 6 | B10: RED SEA MALLS | C10: 2. PLATINUM SPONSOR | D10: Double Page | E10: Yes
A11: 7 | B11: DANAH REAL ESTATE | C11: 3. GOLD SPONSOR | D11: Single Page | E11: Yes
A12: 8 | B12: DALMA MALL | C12: 3. GOLD SPONSOR | D12: Single Page | E12: Yes
A13: 9 | B13: YARDI SYSTEMS | C13: 4. SILVER SPONSOR | D13: Single Page | E13: Yes
A14: 10 | B14: MRI SOFTWARE | C14: 5. BRONZE SPONSOR | D14: — | E14: Yes
A15: 11 | B15: GIFTSTARR | C15: 5. BRONZE SPONSOR | D15: — | E15: Yes
A16: 12 | B16: BURJUMAN | C16: 5. BRONZE SPONSOR | D16: Single Page | E16: Yes
A17: 13 | B17: AMUSEMENT SERVICES INTERNATIONAL LLC | C17: 19. EXHIBITOR | D17: — | E17: Yes
B19: Artwork — full page 210×297mm, double page 420×297mm, CMYK, 3mm bleed. Profile feature — 500–700 words plus images and logo. Dates as YYYY-MM-DD.

Sheet 02 Ads
A1: 02 · ADS — MECSR Directory 2027
A2: Advertising placements owed under the signed 2026 agreements.
A4: SN | B4: COMPANY | C4: TIER | D4: AD SIZE | E4: PAGE ALLOCATED | F4: ARTWORK RECEIVED | G4: STATUS | H4: OWNER | I4: NOTES
A5: 1 | B5: CENOMI CENTERS | C5: 1. DIAMOND SPONSOR | D5: Double Page
A6: 2 | B6: UNIFIED REAL ESTATE DEVELOPMENT | C6: 1. DIAMOND SPONSOR | D6: Double Page
A7: 3 | B7: AL OTHAIM INVESTMENT | C7: 1. DIAMOND SPONSOR | D7: Double Page
A8: 4 | B8: AZAD PROPERTIES | RED MALLS | C8: 1. DIAMOND SPONSOR | D8: Double Page
A9: 5 | B9: KNOWLEDGE ECONOMIC CITY CO. | C9: 2. PLATINUM SPONSOR | D9: Double Page
A10: 6 | B10: RED SEA MALLS | C10: 2. PLATINUM SPONSOR | D10: Double Page
A11: 7 | B11: DANAH REAL ESTATE | C11: 3. GOLD SPONSOR | D11: Single Page
A12: 8 | B12: DALMA MALL | C12: 3. GOLD SPONSOR | D12: Single Page
B14: Artwork — single page 210×297mm, double page 420×297mm, CMYK, 3mm bleed. Page position is allocated by production. Dates as YYYY-MM-DD.

Sheet 03 Corporate Members
A1: 03 · CORPORATE MEMBERS — seats granted under sponsorship agreements
A2: Sponsorship-granted seats only. Corporate memberships bought directly are on sheet 07 Membership 2026.
A4: SN | B4: COMPANY | C4: TIER | D4: SEATS GRANTED | E4: SEATS NOMINATED | F4: SEATS ACTIVATED | G4: MEMBERSHIP START | H4: MEMBERSHIP END | I4: STATUS | J4: OWNER | K4: NOTES
A5: 1 | B5: CENOMI CENTERS | C5: 1. DIAMOND SPONSOR | D5: 35
A6: 2 | B6: UNIFIED REAL ESTATE DEVELOPMENT | C6: 1. DIAMOND SPONSOR | D6: 20
A7: 3 | B7: AL OTHAIM INVESTMENT | C7: 1. DIAMOND SPONSOR | D7: 20
A8: 4 | B8: AZAD PROPERTIES | RED MALLS | C8: 1. DIAMOND SPONSOR | D8: 20
A9: 5 | B9: KNOWLEDGE ECONOMIC CITY CO. | C9: 2. PLATINUM SPONSOR | D9: 10
A10: 6 | B10: RED SEA MALLS | C10: 2. PLATINUM SPONSOR | D10: 16
A11: 7 | B11: DANAH REAL ESTATE | C11: 3. GOLD SPONSOR | D11: 12
A12: 8 | B12: DALMA MALL | C12: 3. GOLD SPONSOR | D12: 15
A13: 9 | B13: YARDI SYSTEMS | C13: 4. SILVER SPONSOR | D13: 4
A14: 10 | B14: MRI SOFTWARE | C14: 5. BRONZE SPONSOR | D14: 4
A15: 11 | B15: GIFTSTARR | C15: 5. BRONZE SPONSOR | D15: 4
A16: 12 | B16: BURJUMAN | C16: 5. BRONZE SPONSOR | D16: 4
A17: 13 | B17: AMUSEMENT SERVICES INTERNATIONAL LLC | C17: 19. EXHIBITOR | D17: 2
C18: TOTAL | D18: =SUM(D5:D17) | E18: =SUM(E5:E17) | F18: =SUM(F5:F17)
B19: Nominated = names received from the company (full name, job title, email, mobile). Activated = account created. Dates as YYYY-MM-DD.

Sheet 04 Flat Plan
A1: 04 · FLAT PLAN — MECSR Directory 2027 (384 pages)
A2: The full plan. Blue columns are the locked structure; yellow columns are yours to fill in. THIS SHEET DRIVES THE HTML DOSSIER — edit here and the page follows.
A4: SN | B4: SECTION | C4: ITEM | D4: TYPE | E4: PP | F4: 2027 PAGES | G4: 2026 PAGES | H4: 2027 COUNT | I4: SUPPLIED BY | J4: SPEC / PLANNING NOTE | K4: SPONSOR / CLIENT | L4: ASSIGNED TO | M4: CONTENT STATUS | N4: DESIGN STATUS | O4: DUE DATE | P4: NOTES
A5: 1 | B5: 01 Front of Book | C5: Front Cover | D5: 📕 Cover | E5: 1 | F5: 1 | G5: — | H5: — | I5: Design | J5: Hardcover concept selected from the 2027 cover proposals PDF
A6: 2 | B6: 01 Front of Book | C6: Inside Front Cover (IFC) AD | D6: 📢 Ad | E6: 1 | F6: 2 | G6: — | H6: — | I6: Sales / Client | J6: Premium position — highest ad tier
A7: 3 | B7: 01 Front of Book | C7: Table of Contents | D7: 📑 TOC | E7: 1 | F7: 3 | G7: — | H7: — | I7: Editorial | J7: Built last, after pagination is frozen
A8: 4 | B8: 01 Front of Book | C8: About the 2027 Edition | D8: 📰 Editorial | E8: 1 | F8: 4 | G8: — | H8: — | I8: Editorial | J8: —
A9: 5 | B9: 01 Front of Book | C9: What's New in 2027 | D9: 📰 Editorial | E9: 1 | F9: 5 | G9: — | H9: — | I9: Editorial | J9: —
A10: 6 | B10: 01 Front of Book | C10: Chairman's Message | D10: 💬 Message | E10: 1 | F10: 6 | G10: — | H10: — | I10: Executive Office | J10: —
A11: 7 | B11: 01 Front of Book | C11: CEO Message | D11: 💬 Message | E11: 1 | F11: 7 | G11: — | H11: — | I11: Executive Office | J11: —
A12: 8 | B12: 01 Front of Book | C12: President's Message | D12: 💬 Message | E12: 1 | F12: 8 | G12: — | H12: — | I12: Executive Office | J12: —
A13: 9 | B13: 01 Front of Book | C13: The People Behind MECSR — The MECSR Team | D13: 📰 Editorial | E13: 1 | F13: 9 | G13: — | H13: — | I13: Editorial | J13: 2026 page carried forward — refresh portraits and titles for 2027
A14: 10 | B14: 01 Front of Book | C14: The People Behind MECSR — Founding Fathers | D14: 📰 Editorial | E14: 1 | F14: 10 | G14: — | H14: — | I14: Editorial | J14: 2026 page carried forward — refresh portraits and titles for 2027
A15: 11 | B15: 01 Front of Book | C15: The People Behind MECSR — Board of Directors | D15: 📰 Editorial | E15: 1 | F15: 11 | G15: — | H15: — | I15: Editorial | J15: 2026 page carried forward — refresh portraits and titles for 2027
A16: 12 | B16: 01 Front of Book | C16: The People Behind MECSR — Global Representatives | D16: 📰 Editorial | E16: 1 | F16: 12 | G16: — | H16: — | I16: Editorial | J16: 2026 page carried forward — refresh portraits and titles for 2027
... A95: 91 | B95: 11 Covers | C95: Back Cover | D95: 📕 Cover | E95: 1 | F95: 384 | G95: 7–8, 311–312, 321–322 | H95: — | I95: Design | J95: 2026: KADEN — highest ad tier
D96: TOTAL PAGES | E96: =SUM(E5:E95) | F96: of 384
B97: Page positions are locked to the 384-page plan (24 printer signatures of 16) — changing PP on one row means taking a page from another. Structural rows (listings, index, methodology) are generated from the master dataset and do not need chasing; commercial and editorial rows do.
B98: PAGES BY TYPE
B99: TYPE | C99: ITEMS | D99: PAGES | E99: SHARE
B100: 📕 Cover | C100: 2 | D100: 2 | E100: 0.0052083333
B101: 📢 Ad | C101: 6 | D101: 6 | E101: 0.015625
B102: ⭐ Showcase | C102: 8 | D102: 16 | E102: 0.041666667
B103: ✍️ Article | C103: 9 | D103: 18 | E103: 0.046875
B104: 🌍 Country Profile | C104: 4 | D104: 8 | E104: 0.020833333
B105: 🏬 Feature | C105: 8 | D105: 8 | E105: 0.020833333
B106: 💬 Message | C106: 3 | D106: 3 | E106: 0.0078125
B107: 📑 TOC | C107: 4 | D107: 7 | E107: 0.018229167
B108: 📰 Editorial | C108: 12 | D108: 18 | E108: 0.046875
B109: 📋 Listing | C109: 34 | D109: 286 | E109: 0.74479167
B110: 🔠 Index | C110: 1 | D110: 12 | E110: 0.03125
B111: TOTAL | C111: =SUM(C100:C110) | D111: =SUM(D100:D110) | E111: =SUM(E100:E110)
B113: COMMERCIAL INVENTORY
B114: Sellable positions (ads, DPS showcases, expert views) | E114: 23
B115: Pages they occupy | E115: 40
B116: Share of the book | E116: 10.4%
B117: Open slots still to sell | E117: 2
B118: Premium positions (IFC p2 · opening showcase pp19–20 · IBC p383 · Back Cover p384) | E118: 4
B121: DEADLINE CASCADE | E121: Set the press date and every milestone recalculates.
B122: PRESS DATE → | C122: 2027-07-01 | D122: ← edit this cell (YYYY-MM-DD)
...

Sheet 05 Service Providers
A1: 05 · SERVICE PROVIDERS — pages 279–297
A2: The 19 categories carried from the 2026 listing, with the page budget each earns. Use this to run the verification and outreach campaign.
A4: SN | B4: CATEGORY | C4: PROVIDERS 2026 | D4: SHARE | E4: PAGES | F4: PER PAGE | G4: OUTREACH SENT | H4: REPLIES | I4: VERIFIED 2027 | J4: LOGO / ARTWORK IN | K4: STATUS | L4: OWNER | M4: NOTES
A5: 1 | B5: Real Estate and Shopping Centre Companies | C5: 229 | D5: 0.26627907 | E5: 4.5 | F5: 51
A6: 2 | B6: Business Consulting and Research | C6: 107 | D6: 0.1244186 | E6: 2 | F6: 54
A7: 3 | B7: Digital Transformation and IT Services | C7: 101 | D7: 0.11744186 | E7: 2 | F7: 50
A8: 4 | B8: Leasing, Asset Management, and Advisory | C8: 75 | D8: 0.087209302 | E8: 1.5 | F8: 50
A9: 5 | B9: Advertising, Marketing, and PR | C9: 60 | D9: 0.069767442 | E9: 1 | F9: 60
A10: 6 | B10: Architecture, Design, and Construction | C10: 60 | D10: 0.069767442 | E10: 1 | F10: 60
A11: 7 | B11: Retail and Entertainment Solutions | C11: 52 | D11: 0.060465116 | E11: 1 | F11: 52
A12: 8 | B12: Events & Exhibitions | C12: 26 | D12: 0.030232558 | E12: 0.5 | F12: 52
A13: 9 | B13: Financial and Professional Services | C13: 26 | D13: 0.030232558 | E13: 0.5 | F13: 52
A14: 10 | B14: Interior Design and Fit-out | C14: 26 | D14: 0.030232558 | E14: 0.5 | F14: 52
A15: 11 | B15: Furnishing, Decorations, and Supplies | C15: 21 | D15: 0.024418605 | E15: 0.5 | F15: 42
A16: 12 | B16: Economic Development and Investment Promotion | C16: 13 | D16: 0.015116279 | E16: 0.5 | F16: 26
... A23: 19 | B23: Visual Merchandising | C23: 3 | D23: 0.0034883721 | E23: 0.5 | F23: 6
B24: TOTAL | C24: =SUM(C5:C23) | D24: =SUM(D5:D23) | E24: =SUM(E5:E23) | F24: of 19 pp
B25: A 0.5-page category shares a page with the next one. PER PAGE is the number of provider entries the layout must fit on a page at that allocation.
B27: CAMPAIGN — send the verification request to the category owner, log the date in OUTREACH SENT, chase at +7 and +14 days, and only move a provider to VERIFIED when the company itself confirms name, category, contact and website. Unverified providers carry over from 2026 with a 'record unconfirmed' marker rather than being dropped.

Sheet 06 Expert Views
A1: 06 · EXPERT VIEWS — pages 34-51
A2: Nine contracted thought-leadership spreads with the 2027 author assigned. Titles are proposed; each is grounded in something the company has publicly done — check the dossier for the basis.
A4: SLOT | B4: SLOT NAME | C4: 2027 PAGES | D4: COMPANY | E4: AUTHOR | F4: JOB TITLE | G4: PROPOSED TITLE | H4: STANDFIRST | I4: TITLE AGREED | J4: WORD COUNT | K4: COPY RECEIVED | L4: HEADSHOT IN | M4: CONTENT STATUS | N4: DESIGN STATUS | O4: OWNER | P4: NOTES
A5: 1 | B5: Expert View 01 | C5: 39-40 | D5: Cenomi Centers | E5: Alison Rehill-Erguven | F5: Chief Executive Officer | G5: What Westfield Actually Changes | H5: A global brand licence is an operating discipline before it is a logo. On what had to change inside the business before the first Westfield centre could open in the Kingdom.
A6: 2 | B6: Expert View 02 | C6: 41-42 | D6: Knowledge Economic City | E6: Dr. Moath Al Yahya | F6: Chief Executive Officer | G6: Ten Million Visitors Who Did Not Come to Shop | H6: Madinah's demand anchor is pilgrimage. Why that makes retail underwriting in a faith-tourism city a different exercise from anywhere else in the region.
A7: 3 | B7: Expert View 03 | C7: 43-44 | D7: Azad Properties | E7: Ayman Al Burti | F7: Chief Executive Officer | G7: A Souq at 720,000 Square Metres | H7: Scale usually flattens the thing it scales. What Souq7 did to keep the format intact while making the economics work.
A8: 4 | B8: Expert View 04 | C8: 45-46 | D8: Red Sea Malls | E8: Ibrahim Al Qasmi | F8: Chief Executive Officer | G8: Twenty Years In, and Trading Better | H8: The case for reworking 10,000 sqm of an existing centre rather than building 100,000 new ones — and what the wellness and beauty categories did to dwell time.
A9: 5 | B9: Expert View 05 | C9: 47-48 | D9: Danah Real Estate | E9: Yasser Al Kaltham | F9: Chief Commercial Officer | G9: Renovating a Mall That Never Closes | H9: Al Rashid Mall has been rebuilt around its shoppers since February 2023 without shutting a single trading day. The operational cost of that decision, and why it was still the right one.
A10: 6 | B10: Expert View 06 | C10: 49-50 | D10: Yardi Systems | E10: Neal Gemassmer | F10: VP & General Manager, International | G10: There Is No AI Without One Set of Numbers | H10: Most landlords are three systems away from being able to use the tools they are being sold. On what a single source of truth actually requires.
A11: 7 | B11: Expert View 07 | C11: 51-52 | D11: MRI Software | E11: Robert Stringer | F11: Managing Director, Middle East | G11: Software That Knows Where It Is | H11: Why regional property platforms fail when they are localised as an afterthought, and what changed when the engineering moved closer to the market.
A12: 8 | B12: Expert View 08 | C12: 53-54 | D12: LuckyOne Mall | E12: Saad Zuberi | F12: Chief Executive Officer | G12: From Mall to District | H12: Pakistan's largest centre is becoming a mixed-use address. What eight residential towers on the same podium do to a retail operating model.
A13: 9 | B13: Expert View 09 | C13: 55-56 | D13: Heartatwork Hospitality Consulting | E13: Will Odwarka | F13: Founder & Chief Executive Officer | G13: The Food Court Is Dead. Long Live the Food Court. | H13: Landlords keep leasing F&B as though it were retail with a kitchen. Thirty years and a thousand openings say otherwise.
B15: Spec — 900-1,100 words for a two-page spread, plus an author headshot at 1200px minimum and two supporting images at 300dpi. Three author names still need confirming before print: Al Othaim's CEO is contradictory across sources, KEC changed CEO mid-2026, and Unified publishes no named executive.

Sheet Overview
A1: OVERVIEW — all entitlements and delivery status
A2: Every signed company against every entitlement. Counts below update from the section sheets.
A4: SN | B4: COMPANY | C4: TIER | D4: DIRECTORY AD | E4: RPM AD | F4: RPM PROFILE | G4: CORPORATE SEATS
A5: 1 | B5: CENOMI CENTERS | C5: 1. DIAMOND SPONSOR | D5: Double Page | E5: Double Page | F5: Yes | G5: 35
A6: 2 | B6: UNIFIED REAL ESTATE DEVELOPMENT | C6: 1. DIAMOND SPONSOR | D6: Double Page | E6: Double Page | F6: Yes | G6: 20
A7: 3 | B7: AL OTHAIM INVESTMENT | C7: 1. DIAMOND SPONSOR | D7: Double Page | E7: Double Page | F7: Yes | G7: 20
A8: 4 | B8: AZAD PROPERTIES | RED MALLS | C8: 1. DIAMOND SPONSOR | D8: Double Page | E8: Double Page + 1 Full Page Ad (Q2 & Q3, add-on) | F8: Yes | G8: 20
A9: 5 | B9: KNOWLEDGE ECONOMIC CITY CO. | C9: 2. PLATINUM SPONSOR | D9: Double Page | E9: Double Page | F9: Yes | G9: 10
A10: 6 | B10: RED SEA MALLS | C10: 2. PLATINUM SPONSOR | D10: Double Page | E10: Double Page | F10: Yes | G10: 16
A11: 7 | B11: DANAH REAL ESTATE | C11: 3. GOLD SPONSOR | D11: Single Page | E11: Single Page | F11: Yes | G11: 12
A12: 8 | B12: DALMA MALL | C12: 3. GOLD SPONSOR | D12: Single Page | E12: Single Page | F12: Yes | G12: 15
A13: 9 | B13: YARDI SYSTEMS | C13: 4. SILVER SPONSOR | D13: — | E13: Single Page | F13: Yes | G13: 4
A14: 10 | B14: MRI SOFTWARE | C14: 5. BRONZE SPONSOR | D14: — | E14: — | F14: Yes | G14: 4
A15: 11 | B15: GIFTSTARR | C15: 5. BRONZE SPONSOR | D15: — | E15: — | F15: Yes | G15: 4
A16: 12 | B16: BURJUMAN | C16: 5. BRONZE SPONSOR | D16: — | E16: Single Page | F16: Yes | G16: 4
A17: 13 | B17: AMUSEMENT SERVICES INTERNATIONAL LLC | C17: 19. EXHIBITOR | D17: — | E17: — | F17: Yes | G17: 2
C18: TOTAL SEATS | G18: =SUM(G5:G17)
A21: DELIVERY STATUS
A22: DELIVERABLE | B22: OWED | C22: NOT STARTED | D22: REQUESTED | E22: IN PROGRESS | F22: RECEIVED | G22: APPROVED | H22: PLACED
A23: RPM advertising | B23: =COUNTIF('01 RPM'!D5:D100,"*Page*") | C23: =COUNTIF('01 RPM'!H5:H100,"Not Started") | D23: =COUNTIF('01 RPM'!H5:H100,"Requested") | E23: =COUNTIF('01 RPM'!H5:H100,"In Progress") | F23: =COUNTIF('01 RPM'!H5:H100,"Received") | G23: =COUNTIF('01 RPM'!H5:H100,"Approved") | H23: =COUNTIF('01 RPM'!H5:H100,"Placed")
A24: RPM profiles | B24: =COUNTIF('01 RPM'!E5:E100,"Yes") | C24: =COUNTIF('01 RPM'!K5:K100,"Not Started") | D24: =COUNTIF('01 RPM'!K5:K100,"Requested") | E24: =COUNTIF('01 RPM'!K5:K100,"In Progress") | F24: =COUNTIF('01 RPM'!K5:K100,"Received") | G24: =COUNTIF('01 RPM'!K5:K100,"Approved") | H24: =COUNTIF('01 RPM'!K5:K100,"Placed")
A25: Directory ads | B25: =COUNTA('02 Ads'!A5:A100) | C25: =COUNTIF('02 Ads'!G5:G100,"Not Started") | D25: =COUNTIF('02 Ads'!G5:G100,"Requested") | E25: =COUNTIF('02 Ads'!G5:G100,"In Progress") | F25: =COUNTIF('02 Ads'!G5:G100,"Received") | G25: =COUNTIF('02 Ads'!G5:G100,"Approved") | H25: =COUNTIF('02 Ads'!G5:G100,"Placed")
A26: Corporate members | B26: =COUNTA('03 Corporate Members'!A5:A100) | C26: =COUNTIF('03 Corporate Members'!I5:I100,"Not Started") | D26: =COUNTIF('03 Corporate Members'!I5:I100,"Requested") | E26: =COUNTIF('03 Corporate Members'!I5:I100,"In Progress") | F26: =COUNTIF('03 Corporate Members'!I5:I100,"Received") | G26: =COUNTIF('03 Corporate Members'!I5:I100,"Approved") | H26: =COUNTIF('03 Corporate Members'!I5:I100,"Placed")
A27: TOTAL | B27: =SUM(B23:B26) | C27: =SUM(C23:C26) | D27: =SUM(D23:D26) | E27: =SUM(E23:E26) | F27: =SUM(F23:F26) | G27: =SUM(G23:G26) | H27: =SUM(H23:H26)
